Workbook

Sheet Страницы
A1: Страница на нашем сайте | B1: Адрес | C1: Сейчас на сайте | D1: Очередь | E1: Спрос кластера, мес. | F1: Небольших сайтов в топ-10 | G1: Средних | H1: Больших | I1: Порталов | J1: Что входит (формат по спросу) | K1: Почему на нашем сайте
A2: Лазерная резка (упор на нержавейку) | B2: /uslugi/lazernaya-rezka/ | C2: Частично — /uslugi/perforaciya-listov/ | D2: 1 | E2: =SUMIFS(Частотка!$E$2:$E$45,Частотка!$A$2:$A$45,"Лазерная резка (упор на нержавейку)",Частотка!$B$2:$B$45,"<>смежный") | F2: =COUNTIFS(Выдача!$A$2:$A$64,"Лазерная резка (упор на нержавейку)",Выдача!$D$2:$D$64,"Мини-сайт") | G2: =COUNTIFS(Выдача!$A$2:$A$64,"Лазерная резка (упор на нержавейку)",Выдача!$D$2:$D$64,"Средний сайт") | H2: =COUNTIFS(Выдача!$A$2:$A$64,"Лазерная резка (упор на нержавейку)",Выдача!$D$2:$D$64,"Большой сайт") | I2: =COUNTIFS(Выдача!$A$2:$A$64,"Лазерная резка (упор на нержавейку)",Выдача!$D$2:$D$64,"Портал / форум / вики") | J2: № 29 Лазерная резка — 2690 (основа страницы) | K2: В топе страницы услуг внутри многостраничных сайтов металлообработки (promexcut, gravernu, metall-24). Резка нержавейки — профиль нашего сайта. Старые адреса /laser/ и /lasertrub/ перенаправить сюда.
A3: Травление и пассивация нержавейки | B3: /uslugi/travlenie-i-passivaciya/ | C3: Нет (упоминание в блоге) | D3: 1 | E3: =SUMIFS(Частотка!$E$2:$E$45,Частотка!$A$2:$A$45,"Травление и пассивация нержавейки",Частотка!$B$2:$B$45,"<>смежный") | F3: =COUNTIFS(Выдача!$A$2:$A$64,"Травление и пассивация нержавейки",Выдача!$D$2:$D$64,"Мини-сайт") | G3: =COUNTIFS(Выдача!$A$2:$A$64,"Травление и пассивация нержавейки",Выдача!$D$2:$D$64,"Средний сайт") | H3: =COUNTIFS(Выдача!$A$2:$A$64,"Травление и пассивация нержавейки",Выдача!$D$2:$D$64,"Большой сайт") | I3: =COUNTIFS(Выдача!$A$2:$A$64,"Травление и пассивация нержавейки",Выдача!$D$2:$D$64,"Портал / форум / вики") | J3: № 25 Пассивация — 680 (основа страницы) № 8 Хим. пас (травление нержавейки) — 220 (отдельный блок) | K3: Топ — статьи, услуг почти нет. Услуга напрямую про нержавейку и усиливает тематику нашего сайта.
A4: Гидроабразивная резка | B4: /uslugi/gidroabrazivnaya-rezka/ | C4: Частично — /uslugi/perforaciya-listov/ | D4: 1 | E4: =SUMIFS(Частотка!$E$2:$E$45,Частотка!$A$2:$A$45,"Гидроабразивная резка",Частотка!$B$2:$B$45,"<>смежный") | F4: =COUNTIFS(Выдача!$A$2:$A$64,"Гидроабразивная резка",Выдача!$D$2:$D$64,"Мини-сайт") | G4: =COUNTIFS(Выдача!$A$2:$A$64,"Гидроабразивная резка",Выдача!$D$2:$D$64,"Средний сайт") | H4: =COUNTIFS(Выдача!$A$2:$A$64,"Гидроабразивная резка",Выдача!$D$2:$D$64,"Большой сайт") | I4: =COUNTIFS(Выдача!$A$2:$A$64,"Гидроабразивная резка",Выдача!$D$2:$D$64,"Портал / форум / вики") | J4: № 30 Гидроабразивная резка — 870 (основа страницы) | K4: Топ смешанный: небольшой kit-cut.ru и страницы услуг utk-steel, promexcut. Услуга металлообработки — место на нашем сайте. Старый адрес /gidroabraziv/ перенаправить сюда.
A5: Электрохимическая полировка нержавейки | B5: /uslugi/elektrohimicheskaya-polirovka/ | C5: Частично — /uslugi/polirovka/ | D5: 1 | E5: =SUMIFS(Частотка!$E$2:$E$45,Частотка!$A$2:$A$45,"Электрохимическая полировка нержавейки",Частотка!$B$2:$B$45,"<>смежный") | F5: =COUNTIFS(Выдача!$A$2:$A$64,"Электрохимическая полировка нержавейки",Выдача!$D$2:$D$64,"Мини-сайт") | G5: =COUNTIFS(Выдача!$A$2:$A$64,"Электрохимическая полировка нержавейки",Выдача!$D$2:$D$64,"Средний сайт") | H5: =COUNTIFS(Выдача!$A$2:$A$64,"Электрохимическая полировка нержавейки",Выдача!$D$2:$D$64,"Большой сайт") | I5: =COUNTIFS(Выдача!$A$2:$A$64,"Электрохимическая полировка нержавейки",Выдача!$D$2:$D$64,"Портал / форум / вики") | J5: № 6 Электрохимическое полирование (нерж.) — 240 (основа страницы) № 7 Электроплазменная полировка — 0 (раздел) | K5: В топе статьи и форумы, услуг мало. Полировка нержавейки для пищевых линий — профиль нашего сайта. Электроплазменная полировка — раздел.
A6: Обзор «Гальванические покрытия» | B6: /uslugi/galvanicheskie-pokrytiya/ | C6: Нет | D6: 1 | E6: =SUMIFS(Частотка!$E$2:$E$45,Частотка!$A$2:$A$45,"Обзор «Гальванические покрытия»",Частотка!$B$2:$B$45,"<>смежный") | F6: =COUNTIFS(Выдача!$A$2:$A$64,"Обзор «Гальванические покрытия»",Выдача!$D$2:$D$64,"Мини-сайт") | G6: =COUNTIFS(Выдача!$A$2:$A$64,"Обзор «Гальванические покрытия»",Выдача!$D$2:$D$64,"Средний сайт") | H6: =COUNTIFS(Выдача!$A$2:$A$64,"Обзор «Гальванические покрытия»",Выдача!$D$2:$D$64,"Большой сайт") | I6: =COUNTIFS(Выдача!$A$2:$A$64,"Обзор «Гальванические покрытия»",Выдача!$D$2:$D$64,"Портал / форум / вики") | J6: № Хаб Хаб «Гальванические покрытия» — 380 (основа страницы) | K6: Необязательно. Обзорная страница со ссылками на небольшие сайты покрытий; в топе обзорные статьи средних сайтов.
A7: Шлифовка: продольная и круглая | B7: /uslugi/shlifovanie/ или новая страница | C7: Возможно — /uslugi/shlifovanie/ | D7: 2 | E7: =SUMIFS(Частотка!$E$2:$E$45,Частотка!$A$2:$A$45,"Шлифовка: продольная и круглая",Частотка!$B$2:$B$45,"<>смежный") | F7: =COUNTIFS(Выдача!$A$2:$A$64,"Шлифовка: продольная и круглая",Выдача!$D$2:$D$64,"Мини-сайт") | G7: =COUNTIFS(Выдача!$A$2:$A$64,"Шлифовка: продольная и круглая",Выдача!$D$2:$D$64,"Средний сайт") | H7: =COUNTIFS(Выдача!$A$2:$A$64,"Шлифовка: продольная и круглая",Выдача!$D$2:$D$64,"Большой сайт") | I7: =COUNTIFS(Выдача!$A$2:$A$64,"Шлифовка: продольная и круглая",Выдача!$D$2:$D$64,"Портал / форум / вики") | J7: № 27 Шлифовка продольная — 300 (основа страницы) № 28 Шлифовка круглая — 120 (отдельный блок) | K7: Уточнить у клиента. Круглая шлифовка — в топе небольшие заводы мехобработки. Если «продольная» — это шлифовка листа, страница уже есть.
C9: Итого спрос страниц | E9: =SUM(E2:E7)
A11: Спрос кластера — сумма запросов его направлений (лист «Частотка»), без смежных запросов уже существующих страниц. Google (Ahrefs RU); с Яндексом примерно ×2–3.
A12: Небольших / средних / больших — конкуренты в топ-10 Google RU по всем запросам кластера (лист «Выдача»), не наш сайт.
A13: Порядок: сначала очередь 1, внутри — по спросу.

Sheet Частотка
A1: Кластер | B1: № у клиента | C1: Направление клиента | D1: Запрос | E1: Объём, Google (Ahrefs RU), мес. | F1: KD | G1: Wordstat точная
A2: Лазерная резка (упор на нержавейку) | B2: 29 | C2: Лазерная резка | D2: лазерная резка металла | E2: 1000 | F2: 0
A3: Лазерная резка (упор на нержавейку) | B3: 29 | C3: Лазерная резка | D3: лазерная резка | E3: 600 | F3: 5
A4: Лазерная резка (упор на нержавейку) | B4: 29 | C4: Лазерная резка | D4: лазерная резка нержавейки | E4: 500 | F4: 0
A5: Лазерная резка (упор на нержавейку) | B5: 29 | C5: Лазерная резка | D5: лазерная резка нержавеющей стали | E5: 300 | F5: 0
A6: Лазерная резка (упор на нержавейку) | B6: 29 | C6: Лазерная резка | D6: резка нержавейки лазером | E6: 200 | F6: 0 | G6: 22
A7: Лазерная резка (упор на нержавейку) | B7: 29 | C7: Лазерная резка | D7: лазерная резка металла нижний новгород | E7: 50 | F7: 0
A8: Лазерная резка (упор на нержавейку) | B8: 29 | C8: Лазерная резка | D8: лазерная резка нижний новгород | E8: 40
A9: Лазерная резка (упор на нержавейку) | B9: 29 | C9: Лазерная резка | D9: лазерная резка нержавейки нижний новгород | E9: 0
A10: Травление и пассивация нержавейки | B10: 25 | C10: Пассивация | D10: пассивация | E10: 300 | F10: 0
A11: Травление и пассивация нержавейки | B11: 25 | C11: Пассивация | D11: пассивация металла | E11: 150 | F11: 0
A12: Травление и пассивация нержавейки | B12: 25 | C12: Пассивация | D12: пассивация нержавейки | E12: 150 | F12: 0
A13: Травление и пассивация нержавейки | B13: 25 | C13: Пассивация | D13: пассивация нержавеющей стали | E13: 80 | F13: 0
A14: Травление и пассивация нержавейки | B14: 8 | C14: Хим. пас (травление нержавейки) | D14: травление металла | E14: 150 | F14: 0
A15: Травление и пассивация нержавейки | B15: 8 | C15: Хим. пас (травление нержавейки) | D15: травление нержавеющей стали | E15: 40
A16: Травление и пассивация нержавейки | B16: 8 | C16: Хим. пас (травление нержавейки) | D16: травление нержавейки | E16: 30 | F16: 0
A17: Травление и пассивация нержавейки | B17: 8 | C17: Хим. пас (травление нержавейки) | D17: травление сварных швов | E17: 0
A18: Травление и пассивация нержавейки | B18: 8 | C18: Хим. пас (травление нержавейки) | D18: травление и пассивация | E18: 0
A19: Гидроабразивная резка | B19: 30 | C19: Гидроабразивная резка | D19: гидроабразивная резка | E19: 350 | F19: 17
A20: Гидроабразивная резка | B20: 30 | C20: Гидроабразивная резка | D20: гидроабразивная резка металла | E20: 300 | F20: 6
A21: Гидроабразивная резка | B21: 30 | C21: Гидроабразивная резка | D21: гидрорезка | E21: 200 | F21: 0
A22: Гидроабразивная резка | B22: 30 | C22: Гидроабразивная резка | D22: гидроабразивная резка нижний новгород | E22: 20
A23: Электрохимическая полировка нержавейки | B23: 6 | C23: Электрохимическое полирование (нерж.) | D23: электрополировка | E23: 90 | F23: 0
A24: Электрохимическая полировка нержавейки | B24: 6 | C24: Электрохимическое полирование (нерж.) | D24: электрохимическая полировка | E24: 80 | F24: 0
A25: Электрохимическая полировка нержавейки | B25: 6 | C25: Электрохимическое полирование (нерж.) | D25: электрохимическая полировка нержавейки | E25: 30 | F25: 0
A26: Электрохимическая полировка нержавейки | B26: 6 | C26: Электрохимическое полирование (нерж.) | D26: электрополировка нержавеющей стали | E26: 30
A27: Электрохимическая полировка нержавейки | B27: 6 | C27: Электрохимическое полирование (нерж.) | D27: электрополировка нержавейки | E27: 10
A28: Электрохимическая полировка нержавейки | B28: 7 | C28: Электроплазменная полировка | D28: электроплазменная полировка | E28: 0
A29: Электрохимическая полировка нержавейки | B29: 7 | C29: Электроплазменная полировка | D29: плазменная полировка | E29: 0
A30: Электрохимическая полировка нержавейки | B30: смежный | C30: Уже есть: /uslugi/polirovka/ | D30: полировка металла | E30: 100 | F30: 0
A31: Электрохимическая полировка нержавейки | B31: смежный | C31: Уже есть: /uslugi/polirovka/ | D31: полировка нержавейки | E31: 70 | F31: 0 | G31: 216
A32: Обзор «Гальванические покрытия» | B32: Хаб | C32: Хаб «Гальванические покрытия» | D32: гальванические покрытия | E32: 150 | F32: 0
A33: Обзор «Гальванические покрытия» | B33: Хаб | C33: Хаб «Гальванические покрытия» | D33: гальваническое покрытие металла | E33: 90 | F33: 0
A34: Обзор «Гальванические покрытия» | B34: Хаб | C34: Хаб «Гальванические покрытия» | D34: нанесение гальванических покрытий | E34: 80 | F34: 0
A35: Обзор «Гальванические покрытия» | B35: Хаб | C35: Хаб «Гальванические покрытия» | D35: услуги гальваники | E35: 40 | F35: 0
A36: Обзор «Гальванические покрытия» | B36: Хаб | C36: Хаб «Гальванические покрытия» | D36: гальваника на заказ | E36: 20
A37: Обзор «Гальванические покрытия» | B37: Хаб | C37: Хаб «Гальванические покрытия» | D37: гальваника нижний новгород | E37: 0
A38: Шлифовка: продольная и круглая | B38: 27 | C38: Шлифовка продольная | D38: шлифовка металла | E38: 250 | F38: 0
A39: Шлифовка: продольная и круглая | B39: 27 | C39: Шлифовка продольная | D39: плоская шлифовка | E39: 30
A40: Шлифовка: продольная и круглая | B40: 27 | C40: Шлифовка продольная | D40: плоское шлифование | E40: 20
...

Sheet Выдача
A1: Кластер | B1: Запрос | C1: Позиция | D1: Тип сайта конкурента | E1: Сайт | F1: Страница в выдаче
A2: Лазерная резка (упор на нержавейку) | B2: лазерная резка нержавейки | C2: 2 | D2: Средний сайт | E2: gravernu.ru | F2: https://gravernu.ru/obrabotka-materialov/lazernaya-rezka/lazernaya-rezka-metallov/rezka-nerzhaveyushhej-stali
A3: Лазерная резка (упор на нержавейку) | B3: лазерная резка нержавейки | C3: 3 | D3: Средний сайт | E3: promexcut.ru | F3: https://promexcut.ru/lazernaya-rezka/nerzhavejushhaya-stal
A4: Лазерная резка (упор на нержавейку) | B4: лазерная резка нержавейки | C4: 4 | D4: Большой сайт | E4: vt-metall.ru | F4: https://vt-metall.ru/articles/138-rezka-nerzhaveiki-laserom/
A5: Лазерная резка (упор на нержавейку) | B5: лазерная резка нержавейки | C5: 6 | D5: Средний сайт | E5: semtreugolnikov.ru | F5: https://semtreugolnikov.ru/rezka-nerzhaveyushchej-stali
A6: Лазерная резка (упор на нержавейку) | B6: лазерная резка нержавейки | C6: 7 | D6: Мини-сайт | E6: perfosteel.ru | F6: https://perfosteel.ru/services/lazernaya-rezka-listovogo-metalla/nerzhaveyushhej-stali/
A7: Лазерная резка (упор на нержавейку) | B7: лазерная резка нержавейки | C7: 8 | D7: Средний сайт | E7: premier-laser.ru | F7: https://premier-laser.ru/lazernaya-rezka-nerzhaveyki/
A8: Лазерная резка (упор на нержавейку) | B8: лазерная резка нержавейки | C8: 9 | D8: Средний сайт | E8: metall-24.ru | F8: https://metall-24.ru/services/rezka-nerzhaveyki/
A9: Лазерная резка (упор на нержавейку) | B9: лазерная резка нержавейки | C9: 10 | D9: Мини-сайт | E9: plazma-spb.ru | F9: https://plazma-spb.ru/lazernaja-rezka-nerjaveuchey-stali/
A10: Лазерная резка (упор на нержавейку) | B10: лазерная резка металла | C10: 2 | D10: Большой сайт | E10: lasercut.ru | F10: https://lasercut.ru/Каталог/Станки
A11: Лазерная резка (упор на нержавейку) | B11: лазерная резка металла | C11: 3 | D11: Портал / форум / вики | E11: ozon.ru | F11: https://www.ozon.ru/lazernaya-rezka-metalla-stanok
A12: Лазерная резка (упор на нержавейку) | B12: лазерная резка металла | C12: 5 | D12: Средний сайт | E12: uptk65.ru | F12: https://uptk65.ru/blog/chto-takoe-lazernaya-rezka
A13: Лазерная резка (упор на нержавейку) | B13: лазерная резка металла | C13: 6 | D13: Средний сайт | E13: mc24.ru | F13: https://mc24.ru/figurnaya-i-khudozhestvennaya
... A63: Шлифовка: продольная и круглая | B63: круглая шлифовка | C63: 10 | D63: Мини-сайт | E63: szdo.net | F63: https://szdo.net/services/kruglaya-i-ploskaya-shlifovka
A64: Шлифовка: продольная и круглая | B64: плоская шлифовка | D64: Нет данных | F64: Выдачи в Ahrefs нет
