Workbook

Sheet Направления
A1: Приоритет | B1: № у клиента | C1: Направление | D1: На сайте | E1: Существующая страница | F1: Что сделать | G1: Страница (URL) | H1: Главный запрос (объём) | I1: Спрос группы, мес. | J1: Где делать (по выдаче) | K1: Кто в топ-10 Google | L1: Тип выдачи | M1: Вывод по выдаче | N1: Все запросы и объёмы | O1: Комментарий
A2: P1 | B2: 29 | C2: Лазерная резка | D2: Частично | E2: /uslugi/perforaciya-listov/ | F2: Новая страница | G2: /uslugi/lazernaya-rezka/ | H2: лазерная резка металла — 1000 | I2: =SUMIFS(Запросы!$C$2:$C$109,Запросы!$A$2:$A$109,B2) | J2: Страница на нашем сайте | K2: ="«лазерная резка нержавейки»: мини "&COUNTIFS(Выдача!$A$2:$A$200,"лазерная резка нержавейки",Выдача!$G$2:$G$200,"Мини-сайт")&" · средн. "&COUNTIFS(Выдача!$A$2:$A$200,"лазерная резка нержавейки",Выдача!$G$2:$G$200,"Средний сайт")&" · больш. "&COUNTIFS(Выдача!$A$2:$A$200,"лазерная резка нержавейки",Выдача!$G$2:$G$200,"Большой сайт")&" · портал "&COUNTIFS(Выдача!$A$2:$A$200,"лазерная резка нержавейки",Выдача!$G$2:$G$200,"Портал / форум / вики") | L2: Коммерческая: страницы услуг металлообработки | M2: В топе страницы услуг внутри средних сайтов металлообработки (promexcut, gravernu, metall-24). По общему «лазерная резка металла» выдача смешана со станками и статьями — целиться в «лазерную резку нержавейки». | N2: лазерная резка металла 1000, лазерная резка 600, лазерная резка нержавейки 500, лазерная резка нержавеющей стали 300, резка нержавейки лазером 200, лазерная резка металла нижний новгород 50, лазерная резка нижний новгород 40, лазерная резка нержавейки нижний новгород 0 | O2: Старые адреса /laser/ и /lasertrub/ перенаправить сюда
A3: P1 | B3: 10 | C3: Анодирование алюминия (бцв, ч, нхр, нв) | D3: Нет | E3: — | F3: Новая страница | G3: /uslugi/galvanicheskie-pokrytiya/anodirovanie/ | H3: анодирование — 900 | I3: =SUMIFS(Запросы!$C$2:$C$109,Запросы!$A$2:$A$109,B3) | J3: Отдельный сайт гальваники | K3: ="«анодирование алюминия»: мини "&COUNTIFS(Выдача!$A$2:$A$200,"анодирование алюминия",Выдача!$G$2:$G$200,"Мини-сайт")&" · средн. "&COUNTIFS(Выдача!$A$2:$A$200,"анодирование алюминия",Выдача!$G$2:$G$200,"Средний сайт")&" · больш. "&COUNTIFS(Выдача!$A$2:$A$200,"анодирование алюминия",Выдача!$G$2:$G$200,"Большой сайт")&" · портал "&COUNTIFS(Выдача!$A$2:$A$200,"анодирование алюминия",Выдача!$G$2:$G$200,"Портал / форум / вики") | L3: Смешанная: мелкие гальваники + статьи | M3: Конкуренты слабые: мини- и средние сайты (DR 0–21), плюс Drive2 и Википедия. Профильный гальванический сайт займёт топ быстрее, чем раздел на сайте нержавейки. | N3: анодирование 900, анодирование алюминия 600, анодное оксидирование 80, анодирование алюминия цена 70, цветное анодирование алюминия 30, анодирование нижний новгород 0 | O3: Разделами на этой странице: № 11, 13, 14, 15
A4: P1 | B4: 1 | C4: Цинкование (бцв, хр, чёрное — П.бцв, П.хр, П.ч) | D4: Нет | E4: — | F4: Новая страница | G4: /uslugi/galvanicheskie-pokrytiya/cinkovanie/ | H4: цинкование — 400 | I4: =SUMIFS(Запросы!$C$2:$C$109,Запросы!$A$2:$A$109,B4) | J4: Отдельный сайт гальваники | K4: ="«гальваническое цинкование»: мини "&COUNTIFS(Выдача!$A$2:$A$200,"гальваническое цинкование",Выдача!$G$2:$G$200,"Мини-сайт")&" · средн. "&COUNTIFS(Выдача!$A$2:$A$200,"гальваническое цинкование",Выдача!$G$2:$G$200,"Средний сайт")&" · больш. "&COUNTIFS(Выдача!$A$2:$A$200,"гальваническое цинкование",Выдача!$G$2:$G$200,"Большой сайт")&" · портал "&COUNTIFS(Выдача!$A$2:$A$200,"гальваническое цинкование",Выдача!$G$2:$G$200,"Портал / форум / вики") | L4: Информационная: статьи о технологии | M4: Услуг в топе почти нет — статьи, Drive2, PDF. По «цинкованию металла» ещё и горячее цинкование. Нужна страница услуги с блоком про технологию. | N4: цинкование 400, цинкование металла 300, гальваническое цинкование 150, цинкование деталей 50, черное цинкование 30, цинкование с хроматированием 20, оцинковка деталей 20, цинкование цена 20, желтое цинкование 10, цинкование крепежа 10, цинкование нижний новгород 0 | O4: В тексте развести с горячим цинкованием
A5: P1 | B5: 25 | C5: Пассивация | D5: Нет | E5: только упоминание в блоге | F5: Новая страница (вместе с № 8) | G5: /uslugi/travlenie-i-passivaciya/ | H5: пассивация — 300 | I5: =SUMIFS(Запросы!$C$2:$C$109,Запросы!$A$2:$A$109,B5) | J5: Страница на нашем сайте | K5: ="«пассивация нержавейки»: мини "&COUNTIFS(Выдача!$A$2:$A$200,"пассивация нержавейки",Выдача!$G$2:$G$200,"Мини-сайт")&" · средн. "&COUNTIFS(Выдача!$A$2:$A$200,"пассивация нержавейки",Выдача!$G$2:$G$200,"Средний сайт")&" · больш. "&COUNTIFS(Выдача!$A$2:$A$200,"пассивация нержавейки",Выдача!$G$2:$G$200,"Большой сайт")&" · портал "&COUNTIFS(Выдача!$A$2:$A$200,"пассивация нержавейки",Выдача!$G$2:$G$200,"Портал / форум / вики") | L5: Информационная: статьи | M5: Топ — статьи на средних и мини-сайтах, услуг почти нет. Профильно для нержавейки: страница «Травление и пассивация» на нашем сайте закроет и спрос, и тематику. | N5: пассивация 300, пассивация металла 150, пассивация нержавейки 150, пассивация нержавеющей стали 80 | O5: Вместе с № 8 спрос около 900. Профильно для нержавейки
A6: P1 | B6: 8 | C6: Хим. пас (травление нержавейки) | D6: Нет | E6: — | F6: Та же страница, что № 25 | G6: /uslugi/travlenie-i-passivaciya/ | H6: травление металла — 150 | I6: =SUMIFS(Запросы!$C$2:$C$109,Запросы!$A$2:$A$109,B6) | J6: Страница на нашем сайте | K6: ="«травление нержавеющей стали»: мини "&COUNTIFS(Выдача!$A$2:$A$200,"травление нержавеющей стали",Выдача!$G$2:$G$200,"Мини-сайт")&" · средн. "&COUNTIFS(Выдача!$A$2:$A$200,"травление нержавеющей стали",Выдача!$G$2:$G$200,"Средний сайт")&" · больш. "&COUNTIFS(Выдача!$A$2:$A$200,"травление нержавеющей стали",Выдача!$G$2:$G$200,"Большой сайт")&" · портал "&COUNTIFS(Выдача!$A$2:$A$200,"травление нержавеющей стали",Выдача!$G$2:$G$200,"Портал / форум / вики") | L6: Информационная (данные Google устаревшие) | M6: Статьи «как травить на дому» на мини-сайтах. Отдельно не продвигать — входит в страницу № 25. | N6: травление металла 150, травление нержавеющей стали 40, травление нержавейки 30, травление сварных швов 0, травление и пассивация 0
A7: P1 | B7: 30 | C7: Гидроабразивная резка | D7: Частично | E7: /uslugi/perforaciya-listov/ | F7: Новая страница | G7: /uslugi/gidroabrazivnaya-rezka/ | H7: гидроабразивная резка — 350 | I7: =SUMIFS(Запросы!$C$2:$C$109,Запросы!$A$2:$A$109,B7) | J7: Страница на нашем сайте | K7: ="«гидроабразивная резка металла»: мини "&COUNTIFS(Выдача!$A$2:$A$200,"гидроабразивная резка металла",Выдача!$G$2:$G$200,"Мини-сайт")&" · средн. "&COUNTIFS(Выдача!$A$2:$A$200,"гидроабразивная резка металла",Выдача!$G$2:$G$200,"Средний сайт")&" · больш. "&COUNTIFS(Выдача!$A$2:$A$200,"гидроабразивная резка металла",Выдача!$G$2:$G$200,"Большой сайт")&" · портал "&COUNTIFS(Выдача!$A$2:$A$200,"гидроабразивная резка металла",Выдача!$G$2:$G$200,"Портал / форум / вики") | L7: Смешанная: мини-сайт под услугу + страницы услуг + статьи | M7: На 2-м месте мини-сайт kit-cut.ru (главная целиком про гидрорезку), рядом страницы услуг utk-steel и promexcut. Страница на нашем сайте подходит; мини-сайт — только если есть свой станок в Нижнем Новгороде. | N7: гидроабразивная резка 350, гидроабразивная резка металла 300, гидрорезка 200, гидроабразивная резка нижний новгород 20 | O7: Старый адрес /gidroabraziv/ перенаправить сюда
A8: P1 | B8: Хаб | C8: Хаб «Гальванические покрытия» | D8: Нет | E8: — | F8: Новая страница (хаб) | G8: /uslugi/galvanicheskie-pokrytiya/ | H8: гальванические покрытия — 150 | I8: =SUMIFS(Запросы!$C$2:$C$109,Запросы!$A$2:$A$109,B8) | J8: Отдельный сайт гальваники | K8: ="«гальванические покрытия»: мини "&COUNTIFS(Выдача!$A$2:$A$200,"гальванические покрытия",Выдача!$G$2:$G$200,"Мини-сайт")&" · средн. "&COUNTIFS(Выдача!$A$2:$A$200,"гальванические покрытия",Выдача!$G$2:$G$200,"Средний сайт")&" · больш. "&COUNTIFS(Выдача!$A$2:$A$200,"гальванические покрытия",Выдача!$G$2:$G$200,"Большой сайт")&" · портал "&COUNTIFS(Выдача!$A$2:$A$200,"гальванические покрытия",Выдача!$G$2:$G$200,"Портал / форум / вики") | L8: Информационная: обзорные статьи | M8: Топ — обзорные статьи на средних сайтах. Это главная страница будущего гальванического сайта. | N8: гальванические покрытия 150, гальваническое покрытие металла 90, нанесение гальванических покрытий 80, услуги гальваники 40, гальваника на заказ 20, гальваника нижний новгород 0 | O8: Ссылки на все покрытия. Общий запрос «гальваника» (2500) в сумму не включён
A9: P1 | B9: 18 | C9: Хромирование твёрдое | D9: Нет | E9: — | F9: Новая страница | G9: /uslugi/galvanicheskie-pokrytiya/hromirovanie/ | H9: хромирование деталей — 250 | I9: =SUMIFS(Запросы!$C$2:$C$109,Запросы!$A$2:$A$109,B9) | J9: Отдельный сайт гальваники | K9: ="«твердое хромирование»: мини "&COUNTIFS(Выдача!$A$2:$A$200,"твердое хромирование",Выдача!$G$2:$G$200,"Мини-сайт")&" · средн. "&COUNTIFS(Выдача!$A$2:$A$200,"твердое хромирование",Выдача!$G$2:$G$200,"Средний сайт")&" · больш. "&COUNTIFS(Выдача!$A$2:$A$200,"твердое хромирование",Выдача!$G$2:$G$200,"Большой сайт")&" · портал "&COUNTIFS(Выдача!$A$2:$A$200,"твердое хромирование",Выдача!$G$2:$G$200,"Портал / форум / вики") | L9: Коммерческая: мини-сайты гальваник (по «хромированию деталей» — авто-хром и маркетплейсы) | M9: «Хромирование деталей» — Avito, Ozon, автотюнинг (декоративный хром). «Твёрдое хромирование» — мини-сайты гальваник (hrom-prom, galvanika-msk). Целиться в техническое твёрдое хромирование. | N9: хромирование 250, хромирование деталей 250, гальваническое хромирование 80, твердое хромирование 20, хромирование штоков 0, хромирование нижний новгород 0 | O9: «хромирование штоков» проверить в Wordstat
A10: P1 | B10: 4 | C10: Гальваническое никелирование (блестящее) | D10: Нет | E10: — | F10: Новая страница | G10: /uslugi/galvanicheskie-pokrytiya/nikelirovanie/ | H10: никелирование — 350 | I10: =SUMIFS(Запросы!$C$2:$C$109,Запросы!$A$2:$A$109,B10) | J10: Отдельный сайт гальваники | K10: ="«никелирование»: мини "&COUNTIFS(Выдача!$A$2:$A$200,"никелирование",Выдача!$G$2:$G$200,"Мини-сайт")&" · средн. "&COUNTIFS(Выдача!$A$2:$A$200,"никелирование",Выдача!$G$2:$G$200,"Средний сайт")&" · больш. "&COUNTIFS(Выдача!$A$2:$A$200,"никелирование",Выдача!$G$2:$G$200,"Большой сайт")&" · портал "&COUNTIFS(Выдача!$A$2:$A$200,"никелирование",Выдача!$G$2:$G$200,"Портал / форум / вики") | L10: Смешанная: узкие гальваники + статьи | M10: Мини- и средние гальванические сайты (chemnikel, 6mkm, zctc), больших игроков нет. | N10: никелирование 350, гальваническое никелирование 60, никелирование металла 50, никелирование деталей 50, блестящее никелирование 0 | O10: Разделом на этой странице: № 5
A11: P1 | B11: 6 | C11: Электрохимическое полирование (нерж.) | D11: Частично | E11: /uslugi/polirovka/ | F11: Новая страница | G11: /uslugi/elektrohimicheskaya-polirovka/ | H11: электрополировка — 90 | I11: =SUMIFS(Запросы!$C$2:$C$109,Запросы!$A$2:$A$109,B11) | J11: Страница на нашем сайте | K11: ="«электрохимическая полировка»: мини "&COUNTIFS(Выдача!$A$2:$A$200,"электрохимическая полировка",Выдача!$G$2:$G$200,"Мини-сайт")&" · средн. "&COUNTIFS(Выдача!$A$2:$A$200,"электрохимическая полировка",Выдача!$G$2:$G$200,"Средний сайт")&" · больш. "&COUNTIFS(Выдача!$A$2:$A$200,"электрохимическая полировка",Выдача!$G$2:$G$200,"Большой сайт")&" · портал "&COUNTIFS(Выдача!$A$2:$A$200,"электрохимическая полировка",Выдача!$G$2:$G$200,"Портал / форум / вики") | L11: Информационная: статьи и форумы | M11: Статьи, Habr, форумы; услуг мало. Профильно для нержавейки (пищевые линии) — страница на нашем сайте. | N11: электрополировка 90, электрохимическая полировка 80, электрохимическая полировка нержавейки 30, электрополировка нержавеющей стали 30, электрополировка нержавейки 10 | O11: Спрос средний, но профильно для нержавейки. Разделом: № 7
A12: P2 | B12: 9 | C12: Хим. оксидирование стали с промасливанием | D12: Нет | E12: — | F12: Новая страница | G12: /uslugi/galvanicheskie-pokrytiya/oksidirovanie-stali/ | H12: воронение металла — 350 | I12: =SUMIFS(Запросы!$C$2:$C$109,Запросы!$A$2:$A$109,B12) | J12: Отдельный сайт гальваники | K12: ="«оксидирование стали»: мини "&COUNTIFS(Выдача!$A$2:$A$200,"оксидирование стали",Выдача!$G$2:$G$200,"Мини-сайт")&" · средн. "&COUNTIFS(Выдача!$A$2:$A$200,"оксидирование стали",Выдача!$G$2:$G$200,"Средний сайт")&" · больш. "&COUNTIFS(Выдача!$A$2:$A$200,"оксидирование стали",Выдача!$G$2:$G$200,"Большой сайт")&" · портал "&COUNTIFS(Выдача!$A$2:$A$200,"оксидирование стали",Выдача!$G$2:$G$200,"Портал / форум / вики") | L12: Смешанная: статьи + услуги гальваник | M12: Мини- и средние сайты (smetiz, vskplast, zctc) плюс Википедия. Конкуренция низкая. | N12: воронение металла 350, оксидирование 250, оксидирование стали 150, химическое оксидирование 100, химическое оксидирование стали 50 | O12: Много бытовых запросов про воронение
A13: P2 | B13: 23 | C13: Хим. фосфатирование с оксидированием | D13: Нет | E13: — | F13: Новая страница | G13: /uslugi/galvanicheskie-pokrytiya/fosfatirovanie/ | H13: фосфатирование — 300 | I13: =SUMIFS(Запросы!$C$2:$C$109,Запросы!$A$2:$A$109,B13) | J13: Отдельный сайт гальваники | K13: ="«фосфатирование металла»: мини "&COUNTIFS(Выдача!$A$2:$A$200,"фосфатирование металла",Выдача!$G$2:$G$200,"Мини-сайт")&" · средн. "&COUNTIFS(Выдача!$A$2:$A$200,"фосфатирование металла",Выдача!$G$2:$G$200,"Средний сайт")&" · больш. "&COUNTIFS(Выдача!$A$2:$A$200,"фосфатирование металла",Выдача!$G$2:$G$200,"Большой сайт")&" · портал "&COUNTIFS(Выдача!$A$2:$A$200,"фосфатирование металла",Выдача!$G$2:$G$200,"Портал / форум / вики") | L13: Информационная | M13: Статьи, Википедия, Drive2; услуги только у узких гальваник. | N13: фосфатирование 300, фосфатирование металла 150, химическое фосфатирование 40
A14: P2 | B14: 12 | C14: Анодирование титана (аноцвет) | D14: Нет | E14: — | F14: Новая страница | G14: /uslugi/galvanicheskie-pokrytiya/anodirovanie-titana/ | H14: анодирование титана — 400 | I14: =SUMIFS(Запросы!$C$2:$C$109,Запросы!$A$2:$A$109,B14) | J14: Отдельный сайт гальваники | K14: ="«анодирование титана»: мини "&COUNTIFS(Выдача!$A$2:$A$200,"анодирование титана",Выдача!$G$2:$G$200,"Мини-сайт")&" · средн. "&COUNTIFS(Выдача!$A$2:$A$200,"анодирование титана",Выдача!$G$2:$G$200,"Средний сайт")&" · больш. "&COUNTIFS(Выдача!$A$2:$A$200,"анодирование титана",Выдача!$G$2:$G$200,"Большой сайт")&" · портал "&COUNTIFS(Выдача!$A$2:$A$200,"анодирование титана",Выдача!$G$2:$G$200,"Портал / форум / вики") | L14: Хобби / форумы + мелкие услуги | M14: Форумы (guns.ru, VK) и мини-сайты; спрос частично частный (ножи, украшения). | N14: анодирование титана 400
A15: P2 | B15: 19 | C15: Серебрение | D15: Нет | E15: — | F15: Новая страница | G15: /uslugi/galvanicheskie-pokrytiya/serebrenie/ | H15: серебрение — 150 | I15: =SUMIFS(Запросы!$C$2:$C$109,Запросы!$A$2:$A$109,B15) | J15: Отдельный сайт гальваники | K15: ="«гальваническое серебрение»: мини "&COUNTIFS(Выдача!$A$2:$A$200,"гальваническое серебрение",Выдача!$G$2:$G$200,"Мини-сайт")&" · средн. "&COUNTIFS(Выдача!$A$2:$A$200,"гальваническое серебрение",Выдача!$G$2:$G$200,"Средний сайт")&" · больш. "&COUNTIFS(Выдача!$A$2:$A$200,"гальваническое серебрение",Выдача!$G$2:$G$200,"Большой сайт")&" · портал "&COUNTIFS(Выдача!$A$2:$A$200,"гальваническое серебрение",Выдача!$G$2:$G$200,"Портал / форум / вики") | L15: Коммерческая: мини-сайты гальваник | M15: Топ почти целиком из мини-сайтов — узкий гальванический сайт здесь в своей среде. | N15: серебрение 150, гальваническое серебрение 150, серебрение металла 50
A16: P2 | B16: 27 | C16: Шлифовка продольная | D16: Возможно | E16: /uslugi/shlifovanie/ | F16: Уточнить у клиента | G16: — | H16: шлифовка металла — 250 | I16: =SUMIFS(Запросы!$C$2:$C$109,Запросы!$A$2:$A$109,B16) | J16: Уточнить у клиента | K16: нет данных | L16: Нет данных в Ahrefs | M16: Выдачи в Ahrefs нет — проверить в Яндексе и уточнить у клиента, что имеется в виду. | N16: шлифовка металла 250, плоская шлифовка 30, плоское шлифование 20, шлифовка металла на заказ 0 | O16: Если это шлифовка листа — страница уже есть («шлифовка нержавейки»: Ahrefs 70, Wordstat 65)
A17: P2 | B17: 16 | C17: Оловянирование | D17: Нет | E17: — | F17: Новая страница | G17: /uslugi/galvanicheskie-pokrytiya/olovyanirovanie/ | H17: лужение — 200 | I17: =SUMIFS(Запросы!$C$2:$C$109,Запросы!$A$2:$A$109,B17) | J17: Отдельный сайт гальваники | K17: ="«оловянирование»: мини "&COUNTIFS(Выдача!$A$2:$A$200,"оловянирование",Выдача!$G$2:$G$200,"Мини-сайт")&" · средн. "&COUNTIFS(Выдача!$A$2:$A$200,"оловянирование",Выдача!$G$2:$G$200,"Средний сайт")&" · больш. "&COUNTIFS(Выдача!$A$2:$A$200,"оловянирование",Выдача!$G$2:$G$200,"Большой сайт")&" · портал "&COUNTIFS(Выдача!$A$2:$A$200,"оловянирование",Выдача!$G$2:$G$200,"Портал / форум / вики") | L17: Коммерческая: мини-сайты гальваник | M17: Почти весь топ — мини-сайты гальваник и производителей гальванических линий. | N17: лужение 200, оловянирование 40, лужение меди 40, гальваническое лужение 10 | O17: Разделом на этой странице: № 17
A18: P2 | B18: 3 | C18: Меднение | D18: Нет | E18: — | F18: Новая страница | G18: /uslugi/galvanicheskie-pokrytiya/mednenie/ | H18: меднение — 100 | I18: =SUMIFS(Запросы!$C$2:$C$109,Запросы!$A$2:$A$109,B18) | J18: Отдельный сайт гальваники | K18: ="«гальваническое меднение»: мини "&COUNTIFS(Выдача!$A$2:$A$200,"гальваническое меднение",Выдача!$G$2:$G$200,"Мини-сайт")&" · средн. "&COUNTIFS(Выдача!$A$2:$A$200,"гальваническое меднение",Выдача!$G$2:$G$200,"Средний сайт")&" · больш. "&COUNTIFS(Выдача!$A$2:$A$200,"гальваническое меднение",Выдача!$G$2:$G$200,"Большой сайт")&" · портал "&COUNTIFS(Выдача!$A$2:$A$200,"гальваническое меднение",Выдача!$G$2:$G$200,"Портал / форум / вики") | L18: Смешанная: гальваники + статья «в домашних условиях» | M18: Мини- и средние гальванические сайты (zctc, ezetek, plast-product); на 1-м месте статья для домашних мастеров. | N18: меднение 100, меднение металла 70, гальваническое меднение 60, меднение алюминия 40
A19: P2 | B19: 20 | C19: Золочение | D19: Нет | E19: — | F19: Новая страница | G19: /uslugi/galvanicheskie-pokrytiya/zolochenie/ | H19: гальваническое золочение — 150 | I19: =SUMIFS(Запросы!$C$2:$C$109,Запросы!$A$2:$A$109,B19) | J19: Отдельный сайт гальваники | K19: ="«гальваническое золочение»: мини "&COUNTIFS(Выдача!$A$2:$A$200,"гальваническое золочение",Выдача!$G$2:$G$200,"Мини-сайт")&" · средн. "&COUNTIFS(Выдача!$A$2:$A$200,"гальваническое золочение",Выдача!$G$2:$G$200,"Средний сайт")&" · больш. "&COUNTIFS(Выдача!$A$2:$A$200,"гальваническое золочение",Выдача!$G$2:$G$200,"Большой сайт")&" · портал "&COUNTIFS(Выдача!$A$2:$A$200,"гальваническое золочение",Выдача!$G$2:$G$200,"Портал / форум / вики") | L19: Коммерческая: мини-сайты | M19: Почти весь топ — мини-сайты, у mademetall и funchrome в выдаче главная страница. Узкий сайт конкурентен. | N19: гальваническое золочение 150, золочение 100
A20: P2 | B20: 2 | C20: Кадмирование (бцв, хр) | D20: Нет | E20: — | F20: Новая страница | G20: /uslugi/galvanicheskie-pokrytiya/kadmirovanie/ | H20: кадмирование — 200 | I20: =SUMIFS(Запросы!$C$2:$C$109,Запросы!$A$2:$A$109,B20) | J20: Отдельный сайт гальваники | K20: ="«кадмирование»: мини "&COUNTIFS(Выдача!$A$2:$A$200,"кадмирование",Выдача!$G$2:$G$200,"Мини-сайт")&" · средн. "&COUNTIFS(Выдача!$A$2:$A$200,"кадмирование",Выдача!$G$2:$G$200,"Средний сайт")&" · больш. "&COUNTIFS(Выдача!$A$2:$A$200,"кадмирование",Выдача!$G$2:$G$200,"Большой сайт")&" · портал "&COUNTIFS(Выдача!$A$2:$A$200,"кадмирование",Выдача!$G$2:$G$200,"Портал / форум / вики") | L20: Коммерческая: мини-сайты гальваник | M20: Википедия + мини-сайты гальваник (galvan.ru, npkhrom, plast-product). Сюда же № 21, 22, 24. | N20: кадмирование 200, кадмирование деталей 30 | O20: Разделами на этой странице: № 21, 22, 24
A21: P3 | B21: 15 | C21: Хим. оксидирование алюминия (электропроводное) | D21: Нет | E21: — | F21: Раздел на странице № 10 | G21: — | H21: хроматирование — 80 | I21: =SUMIFS(Запросы!$C$2:$C$109,Запросы!$A$2:$A$109,B21) | J21: Раздел на другой странице | K21: ="«химическое оксидирование алюминия»: мини "&COUNTIFS(Выдача!$A$2:$A$200,"химическое оксидирование алюминия",Выдача!$G$2:$G$200,"Мини-сайт")&" · средн. "&COUNTIFS(Выдача!$A$2:$A$200,"химическое оксидирование алюминия",Выдача!$G$2:$G$200,"Средний сайт")&" · больш. "&COUNTIFS(Выдача!$A$2:$A$200,"химическое оксидирование алюминия",Выдача!$G$2:$G$200,"Большой сайт")&" · портал "&COUNTIFS(Выдача!$A$2:$A$200,"химическое оксидирование алюминия",Выдача!$G$2:$G$200,"Портал / форум / вики") | L21: Информационная: справочники, PDF | M21: Справочники и учебные PDF — отдельная страница не нужна, раздел на странице № 10. | N21: хроматирование 80, химическое оксидирование алюминия 40, хроматирование алюминия 10
A22: P3 | B22: 28 | C22: Шлифовка круглая | D22: Нет | E22: — | F22: Новая страница | G22: /uslugi/kruglaya-shlifovka/ | H22: круглая шлифовка — 60 | I22: =SUMIFS(Запросы!$C$2:$C$109,Запросы!$A$2:$A$109,B22) | J22: Страница на нашем сайте | K22: ="«круглая шлифовка»: мини "&COUNTIFS(Выдача!$A$2:$A$200,"круглая шлифовка",Выдача!$G$2:$G$200,"Мини-сайт")&" · средн. "&COUNTIFS(Выдача!$A$2:$A$200,"круглая шлифовка",Выдача!$G$2:$G$200,"Средний сайт")&" · больш. "&COUNTIFS(Выдача!$A$2:$A$200,"круглая шлифовка",Выдача!$G$2:$G$200,"Большой сайт")&" · портал "&COUNTIFS(Выдача!$A$2:$A$200,"круглая шлифовка",Выдача!$G$2:$G$200,"Портал / форум / вики") | L22: Коммерческая: небольшие заводы мехобработки | M22: Мини- и средние сайты мехобработки (cometal — главная, profbau, zavkon). Делать, только если услуга реально есть. | N22: круглая шлифовка 60, круглое шлифование 40, круглошлифовальные работы 20
A23: P3 | B23: 5 | C23: Химическое никелирование | D23: Нет | E23: — | F23: Раздел на странице № 4 | G23: — | H23: химическое никелирование — 100 | I23: =SUMIFS(Запросы!$C$2:$C$109,Запросы!$A$2:$A$109,B23) | J23: Раздел на другой странице | K23: ="«химическое никелирование»: мини "&COUNTIFS(Выдача!$A$2:$A$200,"химическое никелирование",Выдача!$G$2:$G$200,"Мини-сайт")&" · средн. "&COUNTIFS(Выдача!$A$2:$A$200,"химическое никелирование",Выдача!$G$2:$G$200,"Средний сайт")&" · больш. "&COUNTIFS(Выдача!$A$2:$A$200,"химическое никелирование",Выдача!$G$2:$G$200,"Большой сайт")&" · портал "&COUNTIFS(Выдача!$A$2:$A$200,"химическое никелирование",Выдача!$G$2:$G$200,"Портал / форум / вики") | L23: Смешанная: гальваники + статьи и монографии | M23: zctc на 1-м месте, дальше статьи и монографии — раздел на странице № 4. | N23: химическое никелирование 100
A24: P3 | B24: 17 | C24: Олово-висмут (матовое) | D24: Нет | E24: — | F24: Раздел на странице № 16 | G24: — | H24: покрытие олово-висмут — 40 | I24: =SUMIFS(Запросы!$C$2:$C$109,Запросы!$A$2:$A$109,B24) | J24: Раздел на другой странице | K24: ="«покрытие олово-висмут»: мини "&COUNTIFS(Выдача!$A$2:$A$200,"покрытие олово-висмут",Выдача!$G$2:$G$200,"Мини-сайт")&" · средн. "&COUNTIFS(Выдача!$A$2:$A$200,"покрытие олово-висмут",Выдача!$G$2:$G$200,"Средний сайт")&" · больш. "&COUNTIFS(Выдача!$A$2:$A$200,"покрытие олово-висмут",Выдача!$G$2:$G$200,"Большой сайт")&" · портал "&COUNTIFS(Выдача!$A$2:$A$200,"покрытие олово-висмут",Выдача!$G$2:$G$200,"Портал / форум / вики") | L24: Коммерческая: мини-сайты | M24: Мини-сайты гальваник и форум; спрос маленький — раздел на странице № 16. | N24: покрытие олово-висмут 40, олово висмут покрытие 40
A25: P3 | B25: 11 | C25: Твёрдое анодирование 20–40 и 40–60 мкм | D25: Нет | E25: — | F25: Раздел на странице № 10 | G25: — | H25: твердое анодирование алюминия — 40 | I25: =SUMIFS(Запросы!$C$2:$C$109,Запросы!$A$2:$A$109,B25) | J25: Раздел на другой странице | K25: нет данных | L25: Нет данных в Ahrefs | M25: Выдачи в Ahrefs нет — раздел на странице № 10. | N25: твердое анодирование алюминия 40, твердое анодирование 20
A26: P3 | B26: 13 | C26: Эматалирование | D26: Нет | E26: — | F26: Раздел на странице № 10 | G26: — | H26: эматалирование — 10 | I26: =SUMIFS(Запросы!$C$2:$C$109,Запросы!$A$2:$A$109,B26) | J26: Раздел на другой странице | K26: нет данных | L26: Нет данных в Ahrefs | M26: Выдачи в Ahrefs нет — раздел на странице № 10. | N26: эматалирование 10
A27: P3 | B27: 14 | C27: Анодирование хромовое | D27: Нет | E27: — | F27: Раздел на странице № 10 | G27: — | H27: нет данных | I27: =SUMIFS(Запросы!$C$2:$C$109,Запросы!$A$2:$A$109,B27) | J27: Раздел на другой странице | K27: — | L27: Не проверялось: спроса нет | M27: Раздел на странице № 10. | N27: — | O27: В Ahrefs данных нет
A28: P3 | B28: 7 | C28: Электроплазменная полировка | D28: Нет | E28: — | F28: Раздел на странице № 6 | G28: — | H28: электроплазменная полировка — 0 | I28: =SUMIFS(Запросы!$C$2:$C$109,Запросы!$A$2:$A$109,B28) | J28: Раздел на другой странице | K28: — | L28: Не проверялось: спроса нет | M28: Раздел на странице № 6. | N28: электроплазменная полировка 0, плазменная полировка 0 | O28: В Google спроса нет — проверить в Wordstat
A29: P3 | B29: 22 | C29: Кадмирование фосфатированное | D29: Нет | E29: — | F29: Раздел на странице № 2 | G29: — | H29: кадмирование с фосфатированием — 0 | I29: =SUMIFS(Запросы!$C$2:$C$109,Запросы!$A$2:$A$109,B29) | J29: Раздел на другой странице | K29: ="«кадмирование»: мини "&COUNTIFS(Выдача!$A$2:$A$200,"кадмирование",Выдача!$G$2:$G$200,"Мини-сайт")&" · средн. "&COUNTIFS(Выдача!$A$2:$A$200,"кадмирование",Выдача!$G$2:$G$200,"Средний сайт")&" · больш. "&COUNTIFS(Выдача!$A$2:$A$200,"кадмирование",Выдача!$G$2:$G$200,"Большой сайт")&" · портал "&COUNTIFS(Выдача!$A$2:$A$200,"кадмирование",Выдача!$G$2:$G$200,"Портал / форум / вики") | L29: См. № 2 | M29: Раздел на странице № 2. | N29: кадмирование с фосфатированием 0
A30: P3 | B30: 24 | C30: Кадмирование фосфатированное с оксидированием | D30: Нет | E30: — | F30: Раздел на странице № 2 | G30: — | H30: нет данных | I30: =SUMIFS(Запросы!$C$2:$C$109,Запросы!$A$2:$A$109,B30) | J30: Раздел на другой странице | K30: ="«кадмирование»: мини "&COUNTIFS(Выдача!$A$2:$A$200,"кадмирование",Выдача!$G$2:$G$200,"Мини-сайт")&" · средн. "&COUNTIFS(Выдача!$A$2:$A$200,"кадмирование",Выдача!$G$2:$G$200,"Средний сайт")&" · больш. "&COUNTIFS(Выдача!$A$2:$A$200,"кадмирование",Выдача!$G$2:$G$200,"Большой сайт")&" · портал "&COUNTIFS(Выдача!$A$2:$A$200,"кадмирование",Выдача!$G$2:$G$200,"Портал / форум / вики") | L30: См. № 2 | M30: Раздел на странице № 2. | N30: — | O30: В Ahrefs данных нет
A31: P3 | B31: 26 | C31: Свинцевание | D31: Нет | E31: — | F31: Строка на странице-хабе | G31: — | H31: свинцевание — 0 | I31: =SUMIFS(Запросы!$C$2:$C$109,Запросы!$A$2:$A$109,B31) | J31: Раздел на другой странице | K31: — | L31: Не проверялось: спроса нет | M31: Строка на странице-хабе гальваники. | N31: свинцевание 0
A32: P3 | B32: 21 | C32: Кадмирование (повтор № 2) | D32: — | E32: — | F32: Входит в страницу № 2 | G32: — | H32: нет данных | I32: =SUMIFS(Запросы!$C$2:$C$109,Запросы!$A$2:$A$109,B32) | J32: Раздел на другой странице | K32: — | L32: — | M32: Дубль № 2 в списке клиента. | N32: — | O32: В списке клиента дублирует № 2
C34: Страница на нашем сайте | F34: =COUNTIF($J$2:$J$32,"Страница на нашем сайте")
C35: Отдельный сайт гальваники (страниц) | F35: =COUNTIF($J$2:$J$32,"Отдельный сайт гальваники")
C36: Раздел на другой странице | F36: =COUNTIF($J$2:$J$32,"Раздел на другой странице")
C37: Уточнить у клиента | F37: =COUNTIF($J$2:$J$32,"Уточнить у клиента")
C38: Позиций в выдаче: мини-сайты | F38: =COUNTIF(Выдача!$G$2:$G$200,"Мини-сайт")
C39: Позиций в выдаче: средние сайты | F39: =COUNTIF(Выдача!$G$2:$G$200,"Средний сайт")
C40: Позиций в выдаче: большие сайты | F40: =COUNTIF(Выдача!$G$2:$G$200,"Большой сайт")
C41: Позиций в выдаче: порталы / форумы / вики | F41: =COUNTIF(Выдача!$G$2:$G$200,"Портал / форум / вики")
...

Sheet Выдача
A1: Запрос | B1: Позиция | C1: Страница в выдаче | D1: Сайт | E1: DR сайта | F1: Запросов у сайта (Google RU) | G1: Тип сайта | H1: Тип страницы (по адресу, ориентировочно)
A2: лазерная резка металла | B2: 2 | C2: https://lasercut.ru/Каталог/Станки | D2: lasercut.ru | E2: 39 | F2: 2331 | G2: Большой сайт | H2: Услуга / каталог
A3: лазерная резка металла | B3: 3 | C3: https://www.ozon.ru/lazernaya-rezka-metalla-stanok | D3: ozon.ru | E3: 91 | G3: Портал / форум / вики | H3: Услуга / каталог
A4: лазерная резка металла | B4: 5 | C4: https://uptk65.ru/blog/chto-takoe-lazernaya-rezka | D4: uptk65.ru | E4: 23 | F4: 256 | G4: Средний сайт | H4: Статья / инфо
A5: лазерная резка металла | B5: 6 | C5: https://mc24.ru/figurnaya-i-khudozhestvennaya | D5: mc24.ru | E5: 15 | F5: 222 | G5: Средний сайт | H5: Прочее
A6: лазерная резка металла | B6: 7 | C6: https://premier-laser.ru/Блог | D6: premier-laser.ru | E6: 5 | F6: 207 | G6: Средний сайт | H6: Статья / инфо
A7: лазерная резка металла | B7: 8 | C7: https://ru.wikipedia.org/wiki/Лазерная_резка | D7: ru.wikipedia.org | E7: 97 | G7: Портал / форум / вики | H7: Статья / инфо
A8: лазерная резка металла | B8: 9 | C8: https://altesa.ru/Каталог | D8: altesa.ru | E8: 11 | F8: 222 | G8: Средний сайт | H8: Услуга / каталог
A9: лазерная резка металла | B9: 10 | C9: https://www.antaeus.ru/Статьи | D9: antaeus.ru | E9: 0.7 | F9: 64 | G9: Мини-сайт | H9: Статья / инфо
A10: лазерная резка нержавейки | B10: 2 | C10: https://gravernu.ru/obrabotka-materialov/lazernaya-rezka/lazernaya-rezka-metallov/rezka-nerzhaveyushhej-stali | D10: gravernu.ru | E10: 2.2 | F10: 568 | G10: Средний сайт | H10: Услуга / каталог
A11: лазерная резка нержавейки | B11: 3 | C11: https://promexcut.ru/lazernaya-rezka/nerzhavejushhaya-stal | D11: promexcut.ru | E11: 35 | F11: 558 | G11: Средний сайт | H11: Услуга / каталог
A12: лазерная резка нержавейки | B12: 4 | C12: https://vt-metall.ru/articles/138-rezka-nerzhaveiki-laserom/ | D12: vt-metall.ru | E12: 26 | F12: 1930 | G12: Большой сайт | H12: Статья / инфо
A13: лазерная резка нержавейки | B13: 6 | C13: https://semtreugolnikov.ru/rezka-nerzhaveyushchej-stali | D13: semtreugolnikov.ru | E13: 2.4 | F13: 222 | G13: Средний сайт | H13: Услуга / каталог
A14: лазерная резка нержавейки | B14: 7 | C14: https://perfosteel.ru/services/lazernaya-rezka-listovogo-metalla/nerzhaveyushhej-stali/ | D14: perfosteel.ru | E14: 0.4 | F14: 87 | G14: Мини-сайт | H14: Услуга / каталог
A15: лазерная резка нержавейки | B15: 8 | C15: https://premier-laser.ru/lazernaya-rezka-nerzhaveyki/ | D15: premier-laser.ru | E15: 5 | F15: 207 | G15: Средний сайт | H15: Услуга / каталог
A16: лазерная резка нержавейки | B16: 9 | C16: https://metall-24.ru/services/rezka-nerzhaveyki/ | D16: metall-24.ru | E16: 0.4 | F16: 345 | G16: Средний сайт | H16: Услуга / каталог
A17: лазерная резка нержавейки | B17: 10 | C17: https://plazma-spb.ru/lazernaja-rezka-nerjaveuchey-stali/ | D17: plazma-spb.ru | E17: 9 | F17: 114 | G17: Мини-сайт | H17: Услуга / каталог
A18: анодирование алюминия | B18: 2 | C18: https://fortis-steel.ru/Услуги | D18: fortis-steel.ru | E18: 4 | F18: 544 | G18: Средний сайт | H18: Услуга / каталог
A19: анодирование алюминия | B19: 3 | C19: https://www.drive2.ru/ | D19: drive2.ru | E19: 79 | G19: Портал / форум / вики | H19: Главная страница сайта
A20: анодирование алюминия | B20: 5 | C20: https://metallcleaner.com/aluminiy-anodirovanie | D20: metallcleaner.com | E20: 10 | F20: 118 | G20: Мини-сайт | H20: Услуга / каталог
A21: анодирование алюминия | B21: 6 | C21: https://rtg-mps.ru/Статьи | D21: rtg-mps.ru | E21: 21 | F21: 428 | G21: Средний сайт | H21: Статья / инфо
A22: анодирование алюминия | B22: 7 | C22: https://oxi-pro.ru/chto-takoe-anodirovanie-alyuminiya | D22: oxi-pro.ru | E22: 0 | F22: 16 | G22: Мини-сайт | H22: Статья / инфо
A23: анодирование алюминия | B23: 8 | C23: https://www.atissteel.ru/anodirovka-aljuminija | D23: atissteel.ru | E23: 3.9 | F23: 858 | G23: Средний сайт | H23: Услуга / каталог
A24: анодирование алюминия | B24: 9 | C24: https://precision-machines.ru/viewtopic | D24: precision-machines.ru | E24: 0.1 | F24: 17 | G24: Мини-сайт | H24: Статья / инфо
A25: анодирование алюминия | B25: 10 | C25: https://ru.wikipedia.org/wiki/Анодирование | D25: ru.wikipedia.org | E25: 97 | G25: Портал / форум / вики | H25: Статья / инфо
A26: гальваническое цинкование | B26: 2 | C26: https://zincor-lkm.ru/articles/cinkovanie-metalla/galvanicheskoe_cinkovanie/ | D26: zincor-lkm.ru | E26: 19 | F26: 488 | G26: Средний сайт | H26: Статья / инфо
A27: гальваническое цинкование | B27: 4 | C27: https://t-zinc.ru/o-kompanii/stati/texnologiya-galvanicheskogo-czinkovaniya.html | D27: t-zinc.ru | E27: 12 | F27: 125 | G27: Мини-сайт | H27: Статья / инфо
A28: гальваническое цинкование | B28: 5 | C28: https://www.drive2.ru/b/571998110557929989/ | D28: drive2.ru | E28: 79 | G28: Портал / форум / вики | H28: Прочее
A29: гальваническое цинкование | B29: 6 | C29: https://zavod-kmk.ru/info/galvanicheskoe-cinkovanie-metalla-tekhnologiya | D29: zavod-kmk.ru | E29: 33 | F29: 766 | G29: Средний сайт | H29: Статья / инфо
A30: гальваническое цинкование | B30: 9 | C30: https://biblioserver.usurt.ru/cgi-bin/irbis64r_13/cgiirbis_64.exe (PDF) | D30: biblioserver.usurt.ru | E30: 51 | G30: Портал / форум / вики | H30: Статья / инфо
A31: гальваническое цинкование | B31: 10 | C31: https://fcm-terminal.com/services/galvanized | D31: fcm-terminal.com | E31: 6 | F31: 16 | G31: Мини-сайт | H31: Услуга / каталог
A32: цинкование металла | B32: 2 | C32: https://www.drive2.ru/b/571998110557929989/ | D32: drive2.ru | E32: 79 | G32: Портал / форум / вики | H32: Прочее
A33: цинкование металла | B33: 3 | C33: https://zavod-kmk.ru/info/vidy-tsinkovaniya-metalla | D33: zavod-kmk.ru | E33: 33 | F33: 766 | G33: Средний сайт | H33: Статья / инфо
A34: цинкование металла | B34: 5 | C34: https://centr-zinc.ru/statie/holodnoe-cinkovanie-v-domashnih-usloviyah/ | D34: centr-zinc.ru | E34: 24 | F34: 10 | G34: Мини-сайт | H34: Статья / инфо
A35: цинкование металла | B35: 6 | C35: https://ru.wikipedia.org/wiki/Цинкование | D35: ru.wikipedia.org | E35: 97 | G35: Портал / форум / вики | H35: Статья / инфо
A36: цинкование металла | B36: 7 | C36: https://market.severstal.com/ru/ru/t/27001 | D36: market.severstal.com | E36: 72 | G36: Портал / форум / вики | H36: Прочее
A37: цинкование металла | B37: 8 | C37: https://promsnab.me/news/_tsinkovanie_2_sposoba_nanesti_tsink_na_metall_/ | D37: promsnab.me | E37: 4.3 | F37: 426 | G37: Средний сайт | H37: Статья / инфо
A38: цинкование металла | B38: 9 | C38: https://www.krepco.ru/blog/tsink1/ | D38: krepco.ru | E38: 19 | F38: 1395 | G38: Большой сайт | H38: Статья / инфо
A39: цинкование металла | B39: 10 | C39: https://steel-ex.ru/services/tsinkovanie/ | D39: steel-ex.ru | E39: 2 | F39: 2049 | G39: Большой сайт | H39: Услуга / каталог
A40: пассивация нержавейки | B40: 2 | C40: https://pharmawater.ru/about/stati/passivaciya-nerzhaveyushchej-stali/ | D40: pharmawater.ru | E40: 27 | F40: 197 | G40: Средний сайт | H40: Статья / инфо
...

Sheet Запросы
A1: № у клиента | B1: Запрос | C1: Объём, Ahrefs RU (Google), мес. | D1: Сложность KD | E1: Wordstat точная
A2: 29 | B2: лазерная резка металла | C2: 1000 | D2: 0
A3: 29 | B3: лазерная резка | C3: 600 | D3: 5
A4: 29 | B4: лазерная резка нержавейки | C4: 500 | D4: 0
A5: 29 | B5: лазерная резка нержавеющей стали | C5: 300 | D5: 0
A6: 29 | B6: резка нержавейки лазером | C6: 200 | D6: 0 | E6: 22
A7: 29 | B7: лазерная резка металла нижний новгород | C7: 50 | D7: 0
A8: 29 | B8: лазерная резка нижний новгород | C8: 40
A9: 29 | B9: лазерная резка нержавейки нижний новгород | C9: 0
A10: 10 | B10: анодирование | C10: 900 | D10: 7
A11: 10 | B11: анодирование алюминия | C11: 600 | D11: 0
A12: 10 | B12: анодное оксидирование | C12: 80 | D12: 0
A13: 10 | B13: анодирование алюминия цена | C13: 70 | D13: 0
A14: 10 | B14: цветное анодирование алюминия | C14: 30 | D14: 14
A15: 10 | B15: анодирование нижний новгород | C15: 0
A16: 1 | B16: цинкование | C16: 400 | D16: 0
A17: 1 | B17: цинкование металла | C17: 300 | D17: 0
A18: 1 | B18: гальваническое цинкование | C18: 150 | D18: 0
A19: 1 | B19: цинкование деталей | C19: 50 | D19: 0
A20: 1 | B20: черное цинкование | C20: 30
A21: 1 | B21: цинкование с хроматированием | C21: 20
A22: 1 | B22: оцинковка деталей | C22: 20
A23: 1 | B23: цинкование цена | C23: 20 | D23: 0
A24: 1 | B24: желтое цинкование | C24: 10
A25: 1 | B25: цинкование крепежа | C25: 10
A26: 1 | B26: цинкование нижний новгород | C26: 0
A27: 25 | B27: пассивация | C27: 300 | D27: 0
A28: 25 | B28: пассивация металла | C28: 150 | D28: 0
A29: 25 | B29: пассивация нержавейки | C29: 150 | D29: 0
A30: 25 | B30: пассивация нержавеющей стали | C30: 80 | D30: 0
A31: 8 | B31: травление металла | C31: 150 | D31: 0
A32: 8 | B32: травление нержавеющей стали | C32: 40
A33: 8 | B33: травление нержавейки | C33: 30 | D33: 0
A34: 8 | B34: травление сварных швов | C34: 0
A35: 8 | B35: травление и пассивация | C35: 0
A36: 30 | B36: гидроабразивная резка | C36: 350 | D36: 17
A37: 30 | B37: гидроабразивная резка металла | C37: 300 | D37: 6
A38: 30 | B38: гидрорезка | C38: 200 | D38: 0
A39: 30 | B39: гидроабразивная резка нижний новгород | C39: 20
A40: Хаб | B40: гальванические покрытия | C40: 150 | D40: 0
...
