Workbook

Sheet Направления
A1: Приоритет | B1: № у клиента | C1: Направление | D1: На сайте | E1: Существующая страница | F1: Что сделать | G1: Страница (URL) | H1: Главный запрос (объём) | I1: Спрос группы, мес. | J1: Все запросы и объёмы | K1: Комментарий
A2: P1 | B2: 29 | C2: Лазерная резка | D2: Частично | E2: /uslugi/perforaciya-listov/ | F2: Новая страница | G2: /uslugi/lazernaya-rezka/ | H2: лазерная резка металла — 1000 | I2: =SUMIFS(Запросы!$C$2:$C$109,Запросы!$A$2:$A$109,B2) | J2: лазерная резка металла 1000, лазерная резка 600, лазерная резка нержавейки 500, лазерная резка нержавеющей стали 300, резка нержавейки лазером 200, лазерная резка металла нижний новгород 50, лазерная резка нижний новгород 40, лазерная резка нержавейки нижний новгород 0 | K2: Старые адреса /laser/ и /lasertrub/ перенаправить сюда
A3: P1 | B3: 10 | C3: Анодирование алюминия (бцв, ч, нхр, нв) | D3: Нет | E3: — | F3: Новая страница | G3: /uslugi/galvanicheskie-pokrytiya/anodirovanie/ | H3: анодирование — 900 | I3: =SUMIFS(Запросы!$C$2:$C$109,Запросы!$A$2:$A$109,B3) | J3: анодирование 900, анодирование алюминия 600, анодное оксидирование 80, анодирование алюминия цена 70, цветное анодирование алюминия 30, анодирование нижний новгород 0 | K3: Разделами на этой странице: № 11, 13, 14, 15
A4: P1 | B4: 1 | C4: Цинкование (бцв, хр, чёрное — П.бцв, П.хр, П.ч) | D4: Нет | E4: — | F4: Новая страница | G4: /uslugi/galvanicheskie-pokrytiya/cinkovanie/ | H4: цинкование — 400 | I4: =SUMIFS(Запросы!$C$2:$C$109,Запросы!$A$2:$A$109,B4) | J4: цинкование 400, цинкование металла 300, гальваническое цинкование 150, цинкование деталей 50, черное цинкование 30, цинкование с хроматированием 20, оцинковка деталей 20, цинкование цена 20, желтое цинкование 10, цинкование крепежа 10, цинкование нижний новгород 0 | K4: В тексте развести с горячим цинкованием
A5: P1 | B5: 25 | C5: Пассивация | D5: Нет | E5: только упоминание в блоге | F5: Новая страница (вместе с № 8) | G5: /uslugi/travlenie-i-passivaciya/ | H5: пассивация — 300 | I5: =SUMIFS(Запросы!$C$2:$C$109,Запросы!$A$2:$A$109,B5) | J5: пассивация 300, пассивация металла 150, пассивация нержавейки 150, пассивация нержавеющей стали 80 | K5: Вместе с № 8 спрос около 900. Профильно для нержавейки
A6: P1 | B6: 8 | C6: Хим. пас (травление нержавейки) | D6: Нет | E6: — | F6: Та же страница, что № 25 | G6: /uslugi/travlenie-i-passivaciya/ | H6: травление металла — 150 | I6: =SUMIFS(Запросы!$C$2:$C$109,Запросы!$A$2:$A$109,B6) | J6: травление металла 150, травление нержавеющей стали 40, травление нержавейки 30, травление сварных швов 0, травление и пассивация 0
A7: P1 | B7: 30 | C7: Гидроабразивная резка | D7: Частично | E7: /uslugi/perforaciya-listov/ | F7: Новая страница | G7: /uslugi/gidroabrazivnaya-rezka/ | H7: гидроабразивная резка — 350 | I7: =SUMIFS(Запросы!$C$2:$C$109,Запросы!$A$2:$A$109,B7) | J7: гидроабразивная резка 350, гидроабразивная резка металла 300, гидрорезка 200, гидроабразивная резка нижний новгород 20 | K7: Старый адрес /gidroabraziv/ перенаправить сюда
A8: P1 | B8: Хаб | C8: Хаб «Гальванические покрытия» | D8: Нет | E8: — | F8: Новая страница (хаб) | G8: /uslugi/galvanicheskie-pokrytiya/ | H8: гальванические покрытия — 150 | I8: =SUMIFS(Запросы!$C$2:$C$109,Запросы!$A$2:$A$109,B8) | J8: гальванические покрытия 150, гальваническое покрытие металла 90, нанесение гальванических покрытий 80, услуги гальваники 40, гальваника на заказ 20, гальваника нижний новгород 0 | K8: Ссылки на все покрытия. Общий запрос «гальваника» (2500) в сумму не включён
A9: P1 | B9: 18 | C9: Хромирование твёрдое | D9: Нет | E9: — | F9: Новая страница | G9: /uslugi/galvanicheskie-pokrytiya/hromirovanie/ | H9: хромирование деталей — 250 | I9: =SUMIFS(Запросы!$C$2:$C$109,Запросы!$A$2:$A$109,B9) | J9: хромирование 250, хромирование деталей 250, гальваническое хромирование 80, твердое хромирование 20, хромирование штоков 0, хромирование нижний новгород 0 | K9: «хромирование штоков» проверить в Wordstat
A10: P1 | B10: 4 | C10: Гальваническое никелирование (блестящее) | D10: Нет | E10: — | F10: Новая страница | G10: /uslugi/galvanicheskie-pokrytiya/nikelirovanie/ | H10: никелирование — 350 | I10: =SUMIFS(Запросы!$C$2:$C$109,Запросы!$A$2:$A$109,B10) | J10: никелирование 350, гальваническое никелирование 60, никелирование металла 50, никелирование деталей 50, блестящее никелирование 0 | K10: Разделом на этой странице: № 5
A11: P1 | B11: 6 | C11: Электрохимическое полирование (нерж.) | D11: Частично | E11: /uslugi/polirovka/ | F11: Новая страница | G11: /uslugi/elektrohimicheskaya-polirovka/ | H11: электрополировка — 90 | I11: =SUMIFS(Запросы!$C$2:$C$109,Запросы!$A$2:$A$109,B11) | J11: электрополировка 90, электрохимическая полировка 80, электрохимическая полировка нержавейки 30, электрополировка нержавеющей стали 30, электрополировка нержавейки 10 | K11: Спрос средний, но профильно для нержавейки. Разделом: № 7
A12: P2 | B12: 9 | C12: Хим. оксидирование стали с промасливанием | D12: Нет | E12: — | F12: Новая страница | G12: /uslugi/galvanicheskie-pokrytiya/oksidirovanie-stali/ | H12: воронение металла — 350 | I12: =SUMIFS(Запросы!$C$2:$C$109,Запросы!$A$2:$A$109,B12) | J12: воронение металла 350, оксидирование 250, оксидирование стали 150, химическое оксидирование 100, химическое оксидирование стали 50 | K12: Много бытовых запросов про воронение
A13: P2 | B13: 23 | C13: Хим. фосфатирование с оксидированием | D13: Нет | E13: — | F13: Новая страница | G13: /uslugi/galvanicheskie-pokrytiya/fosfatirovanie/ | H13: фосфатирование — 300 | I13: =SUMIFS(Запросы!$C$2:$C$109,Запросы!$A$2:$A$109,B13) | J13: фосфатирование 300, фосфатирование металла 150, химическое фосфатирование 40
A14: P2 | B14: 12 | C14: Анодирование титана (аноцвет) | D14: Нет | E14: — | F14: Новая страница | G14: /uslugi/galvanicheskie-pokrytiya/anodirovanie-titana/ | H14: анодирование титана — 400 | I14: =SUMIFS(Запросы!$C$2:$C$109,Запросы!$A$2:$A$109,B14) | J14: анодирование титана 400
A15: P2 | B15: 19 | C15: Серебрение | D15: Нет | E15: — | F15: Новая страница | G15: /uslugi/galvanicheskie-pokrytiya/serebrenie/ | H15: серебрение — 150 | I15: =SUMIFS(Запросы!$C$2:$C$109,Запросы!$A$2:$A$109,B15) | J15: серебрение 150, гальваническое серебрение 150, серебрение металла 50
A16: P2 | B16: 27 | C16: Шлифовка продольная | D16: Возможно | E16: /uslugi/shlifovanie/ | F16: Уточнить у клиента | G16: — | H16: шлифовка металла — 250 | I16: =SUMIFS(Запросы!$C$2:$C$109,Запросы!$A$2:$A$109,B16) | J16: шлифовка металла 250, плоская шлифовка 30, плоское шлифование 20, шлифовка металла на заказ 0 | K16: Если это шлифовка листа — страница уже есть («шлифовка нержавейки»: Ahrefs 70, Wordstat 65)
A17: P2 | B17: 16 | C17: Оловянирование | D17: Нет | E17: — | F17: Новая страница | G17: /uslugi/galvanicheskie-pokrytiya/olovyanirovanie/ | H17: лужение — 200 | I17: =SUMIFS(Запросы!$C$2:$C$109,Запросы!$A$2:$A$109,B17) | J17: лужение 200, оловянирование 40, лужение меди 40, гальваническое лужение 10 | K17: Разделом на этой странице: № 17
A18: P2 | B18: 3 | C18: Меднение | D18: Нет | E18: — | F18: Новая страница | G18: /uslugi/galvanicheskie-pokrytiya/mednenie/ | H18: меднение — 100 | I18: =SUMIFS(Запросы!$C$2:$C$109,Запросы!$A$2:$A$109,B18) | J18: меднение 100, меднение металла 70, гальваническое меднение 60, меднение алюминия 40
A19: P2 | B19: 20 | C19: Золочение | D19: Нет | E19: — | F19: Новая страница | G19: /uslugi/galvanicheskie-pokrytiya/zolochenie/ | H19: гальваническое золочение — 150 | I19: =SUMIFS(Запросы!$C$2:$C$109,Запросы!$A$2:$A$109,B19) | J19: гальваническое золочение 150, золочение 100
A20: P2 | B20: 2 | C20: Кадмирование (бцв, хр) | D20: Нет | E20: — | F20: Новая страница | G20: /uslugi/galvanicheskie-pokrytiya/kadmirovanie/ | H20: кадмирование — 200 | I20: =SUMIFS(Запросы!$C$2:$C$109,Запросы!$A$2:$A$109,B20) | J20: кадмирование 200, кадмирование деталей 30 | K20: Разделами на этой странице: № 21, 22, 24
A21: P3 | B21: 15 | C21: Хим. оксидирование алюминия (электропроводное) | D21: Нет | E21: — | F21: Раздел на странице № 10 | G21: — | H21: хроматирование — 80 | I21: =SUMIFS(Запросы!$C$2:$C$109,Запросы!$A$2:$A$109,B21) | J21: хроматирование 80, химическое оксидирование алюминия 40, хроматирование алюминия 10
A22: P3 | B22: 28 | C22: Шлифовка круглая | D22: Нет | E22: — | F22: Новая страница | G22: /uslugi/kruglaya-shlifovka/ | H22: круглая шлифовка — 60 | I22: =SUMIFS(Запросы!$C$2:$C$109,Запросы!$A$2:$A$109,B22) | J22: круглая шлифовка 60, круглое шлифование 40, круглошлифовальные работы 20
A23: P3 | B23: 5 | C23: Химическое никелирование | D23: Нет | E23: — | F23: Раздел на странице № 4 | G23: — | H23: химическое никелирование — 100 | I23: =SUMIFS(Запросы!$C$2:$C$109,Запросы!$A$2:$A$109,B23) | J23: химическое никелирование 100
A24: P3 | B24: 17 | C24: Олово-висмут (матовое) | D24: Нет | E24: — | F24: Раздел на странице № 16 | G24: — | H24: покрытие олово-висмут — 40 | I24: =SUMIFS(Запросы!$C$2:$C$109,Запросы!$A$2:$A$109,B24) | J24: покрытие олово-висмут 40, олово висмут покрытие 40
A25: P3 | B25: 11 | C25: Твёрдое анодирование 20–40 и 40–60 мкм | D25: Нет | E25: — | F25: Раздел на странице № 10 | G25: — | H25: твердое анодирование алюминия — 40 | I25: =SUMIFS(Запросы!$C$2:$C$109,Запросы!$A$2:$A$109,B25) | J25: твердое анодирование алюминия 40, твердое анодирование 20
A26: P3 | B26: 13 | C26: Эматалирование | D26: Нет | E26: — | F26: Раздел на странице № 10 | G26: — | H26: эматалирование — 10 | I26: =SUMIFS(Запросы!$C$2:$C$109,Запросы!$A$2:$A$109,B26) | J26: эматалирование 10
A27: P3 | B27: 14 | C27: Анодирование хромовое | D27: Нет | E27: — | F27: Раздел на странице № 10 | G27: — | H27: нет данных | I27: =SUMIFS(Запросы!$C$2:$C$109,Запросы!$A$2:$A$109,B27) | J27: — | K27: В Ahrefs данных нет
A28: P3 | B28: 7 | C28: Электроплазменная полировка | D28: Нет | E28: — | F28: Раздел на странице № 6 | G28: — | H28: электроплазменная полировка — 0 | I28: =SUMIFS(Запросы!$C$2:$C$109,Запросы!$A$2:$A$109,B28) | J28: электроплазменная полировка 0, плазменная полировка 0 | K28: В Google спроса нет — проверить в Wordstat
A29: P3 | B29: 22 | C29: Кадмирование фосфатированное | D29: Нет | E29: — | F29: Раздел на странице № 2 | G29: — | H29: кадмирование с фосфатированием — 0 | I29: =SUMIFS(Запросы!$C$2:$C$109,Запросы!$A$2:$A$109,B29) | J29: кадмирование с фосфатированием 0
A30: P3 | B30: 24 | C30: Кадмирование фосфатированное с оксидированием | D30: Нет | E30: — | F30: Раздел на странице № 2 | G30: — | H30: нет данных | I30: =SUMIFS(Запросы!$C$2:$C$109,Запросы!$A$2:$A$109,B30) | J30: — | K30: В Ahrefs данных нет
A31: P3 | B31: 26 | C31: Свинцевание | D31: Нет | E31: — | F31: Строка на странице-хабе | G31: — | H31: свинцевание — 0 | I31: =SUMIFS(Запросы!$C$2:$C$109,Запросы!$A$2:$A$109,B31) | J31: свинцевание 0
A32: P3 | B32: 21 | C32: Кадмирование (повтор № 2) | D32: — | E32: — | F32: Входит в страницу № 2 | G32: — | H32: нет данных | I32: =SUMIFS(Запросы!$C$2:$C$109,Запросы!$A$2:$A$109,B32) | J32: — | K32: В списке клиента дублирует № 2
C34: Новых страниц всего | F34: =COUNTIF($F$2:$F$32,"Новая*")
C35: из них P1 | F35: =COUNTIFS($A$2:$A$32,"P1",$F$2:$F$32,"Новая*")
C36: из них P2 | F36: =COUNTIFS($A$2:$A$32,"P2",$F$2:$F$32,"Новая*")
C37: из них P3 | F37: =COUNTIFS($A$2:$A$32,"P3",$F$2:$F$32,"Новая*")
C38: Разделом на другой странице | F38: =COUNTIF($F$2:$F$32,"Раздел*")+COUNTIF($F$2:$F$32,"Та же*")+COUNTIF($F$2:$F$32,"Строка*")+COUNTIF($F$2:$F$32,"Входит*")
C39: Уточнить у клиента | F39: =COUNTIF($F$2:$F$32,"Уточнить*")
C41: Как читать: «Спрос группы» — сумма объёмов всех запросов направления с листа «Запросы» (считается формулой).
C42: Источник объёмов: Ahrefs Keywords Explorer, Россия, только Google, среднемесячный объём, выгрузка 15.09.2026. Яндекс не учтён — реальный спрос примерно в 2–3 раза выше; соотношение между направлениями сохраняется.
...

Sheet Запросы
A1: № у клиента | B1: Запрос | C1: Объём, Ahrefs RU (Google), мес. | D1: Сложность KD | E1: Wordstat точная
A2: 29 | B2: лазерная резка металла | C2: 1000 | D2: 0
A3: 29 | B3: лазерная резка | C3: 600 | D3: 5
A4: 29 | B4: лазерная резка нержавейки | C4: 500 | D4: 0
A5: 29 | B5: лазерная резка нержавеющей стали | C5: 300 | D5: 0
A6: 29 | B6: резка нержавейки лазером | C6: 200 | D6: 0 | E6: 22
A7: 29 | B7: лазерная резка металла нижний новгород | C7: 50 | D7: 0
A8: 29 | B8: лазерная резка нижний новгород | C8: 40
A9: 29 | B9: лазерная резка нержавейки нижний новгород | C9: 0
A10: 10 | B10: анодирование | C10: 900 | D10: 7
A11: 10 | B11: анодирование алюминия | C11: 600 | D11: 0
A12: 10 | B12: анодное оксидирование | C12: 80 | D12: 0
A13: 10 | B13: анодирование алюминия цена | C13: 70 | D13: 0
A14: 10 | B14: цветное анодирование алюминия | C14: 30 | D14: 14
A15: 10 | B15: анодирование нижний новгород | C15: 0
A16: 1 | B16: цинкование | C16: 400 | D16: 0
A17: 1 | B17: цинкование металла | C17: 300 | D17: 0
A18: 1 | B18: гальваническое цинкование | C18: 150 | D18: 0
A19: 1 | B19: цинкование деталей | C19: 50 | D19: 0
A20: 1 | B20: черное цинкование | C20: 30
A21: 1 | B21: цинкование с хроматированием | C21: 20
A22: 1 | B22: оцинковка деталей | C22: 20
A23: 1 | B23: цинкование цена | C23: 20 | D23: 0
A24: 1 | B24: желтое цинкование | C24: 10
A25: 1 | B25: цинкование крепежа | C25: 10
A26: 1 | B26: цинкование нижний новгород | C26: 0
A27: 25 | B27: пассивация | C27: 300 | D27: 0
A28: 25 | B28: пассивация металла | C28: 150 | D28: 0
A29: 25 | B29: пассивация нержавейки | C29: 150 | D29: 0
A30: 25 | B30: пассивация нержавеющей стали | C30: 80 | D30: 0
A31: 8 | B31: травление металла | C31: 150 | D31: 0
A32: 8 | B32: травление нержавеющей стали | C32: 40
A33: 8 | B33: травление нержавейки | C33: 30 | D33: 0
A34: 8 | B34: травление сварных швов | C34: 0
A35: 8 | B35: травление и пассивация | C35: 0
A36: 30 | B36: гидроабразивная резка | C36: 350 | D36: 17
A37: 30 | B37: гидроабразивная резка металла | C37: 300 | D37: 6
A38: 30 | B38: гидрорезка | C38: 200 | D38: 0
A39: 30 | B39: гидроабразивная резка нижний новгород | C39: 20
A40: Хаб | B40: гальванические покрытия | C40: 150 | D40: 0
...
